Traceback (most recent call last):
  File "C:\Users\kwagner\miniconda3\envs\jedm\lib\site-packages\jupyter_cache\executors\utils.py", line 58, in single_nb_execution
    executenb(
  File "C:\Users\kwagner\miniconda3\envs\jedm\lib\site-packages\nbclient\client.py", line 1204, in execute
    return NotebookClient(nb=nb, resources=resources, km=km, **kwargs).execute()
  File "C:\Users\kwagner\miniconda3\envs\jedm\lib\site-packages\nbclient\util.py", line 84, in wrapped
    return just_run(coro(*args, **kwargs))
  File "C:\Users\kwagner\miniconda3\envs\jedm\lib\site-packages\nbclient\util.py", line 62, in just_run
    return loop.run_until_complete(coro)
  File "C:\Users\kwagner\miniconda3\envs\jedm\lib\asyncio\base_events.py", line 647, in run_until_complete
    return future.result()
  File "C:\Users\kwagner\miniconda3\envs\jedm\lib\site-packages\nbclient\client.py", line 663, in async_execute
    await self.async_execute_cell(
  File "C:\Users\kwagner\miniconda3\envs\jedm\lib\site-packages\nbclient\client.py", line 965, in async_execute_cell
    await self._check_raise_for_error(cell, cell_index, exec_reply)
  File "C:\Users\kwagner\miniconda3\envs\jedm\lib\site-packages\nbclient\client.py", line 862, in _check_raise_for_error
    raise CellExecutionError.from_cell_and_msg(cell, exec_reply_content)
nbclient.exceptions.CellExecutionError: An error occurred while executing the following cell:
------------------

# check the y limits
print(round(data_agg_[data_agg_['T'].isin((types))]['Count'].max(),0))
max_count = round(data_agg_[data_agg_['T'].isin((types))]['Count'].max()*1.1,0)
max_dist = round(data_[data_['T'].isin((types))]['Mean_D'].max()*1.1,0)

print(max_count, max_dist)
# 420
# 17
------------------

[1;31m---------------------------------------------------------------------------[0m
[1;31mNameError[0m                                 Traceback (most recent call last)
Cell [1;32mIn[14], line 2[0m
[0;32m      1[0m [38;5;66;03m# check the y limits[39;00m
[1;32m----> 2[0m [38;5;28mprint[39m([38;5;28mround[39m(data_agg_[data_agg_[[38;5;124m'[39m[38;5;124mT[39m[38;5;124m'[39m][38;5;241m.[39misin(([43mtypes[49m))][[38;5;124m'[39m[38;5;124mCount[39m[38;5;124m'[39m][38;5;241m.[39mmax(),[38;5;241m0[39m))
[0;32m      3[0m max_count [38;5;241m=[39m [38;5;28mround[39m(data_agg_[data_agg_[[38;5;124m'[39m[38;5;124mT[39m[38;5;124m'[39m][38;5;241m.[39misin((types))][[38;5;124m'[39m[38;5;124mCount[39m[38;5;124m'[39m][38;5;241m.[39mmax()[38;5;241m*[39m[38;5;241m1.1[39m,[38;5;241m0[39m)
[0;32m      4[0m max_dist [38;5;241m=[39m [38;5;28mround[39m(data_[data_[[38;5;124m'[39m[38;5;124mT[39m[38;5;124m'[39m][38;5;241m.[39misin((types))][[38;5;124m'[39m[38;5;124mMean_D[39m[38;5;124m'[39m][38;5;241m.[39mmax()[38;5;241m*[39m[38;5;241m1.1[39m,[38;5;241m0[39m)

[1;31mNameError[0m: name 'types' is not defined
NameError: name 'types' is not defined

